Workbook
Name K9101992: 'ZK Ağırlıklı Ortalama Oran'!$I$91227

Sheet TLZK Kal
A1: Zorunlu Karşılığa Tabi Türk Lirası Kalemler (milyon TL)
A2: Yükümlülük Tarihi | B2: Tesis Başlangıç Tarihi | C2: Tesis Bitiş Tarihi | D2: Toplam | E2: Vadesiz mevduat ve özel cari hesap | F2: 1 aya kadar (1 ay dahil) vadeli mevduat /katılma hesabı | G2: 3 aya kadar (3 ay dahil) vadeli mevduat /katılma hesabı | H2: 6 aya kadar (6 ay dahil) vadeli mevduat /katılma hesabı | I2: 1 yıla kadar vadeli mevduat /katılma hesabı | J2: 1 yıl ve daha uzun vadeli mevduat /katılma hesabı | K2: 1 yıla kadar (1 yıl dahil) vadeli mevduat dışı yük. | L2: 3 yıla kadar (3 yıl dahil) vadeli mevduat dışı yük. | M2: 3 yıldan uzun vadeli mevduat dışı yük.
A3: 40802 | B3: 40816 | C3: 40829 | D3: =+SUM(E3:Q3) -> 519379.34 | E3: 71112.821 | F3: 63321.84 | G3: 261180.15 | H3: 41852.786 | I3: 9850.851 | J3: 12543.614 | K3: 59517.279
A4: 40816 | B4: 40830 | C4: 40843 | D4: =+SUM(E4:Q4) -> 522453.46 | E4: 70923.261 | F4: 62134.486 | G4: 260081.52 | H4: 42377.79 | I4: 10125.583 | J4: 12944.388 | K4: 58115.975 | L4: 2903.918 | M4: 2846.548
A5: 40830 | B5: 40844 | C5: 40857 | D5: =+SUM(E5:Q5) -> 521678.21 | E5: 72315.194 | F5: 60884.95 | G5: 261347.82 | H5: 42109.699 | I5: 10073.761 | J5: 13160.675 | K5: 56083.511 | L5: 2820.666 | M5: 2881.929
A6: 40844 | B6: 40858 | C6: 40871 | D6: =+SUM(E6:Q6) -> 511549.6 | E6: 69072.684 | F6: 57872.41 | G6: 261047.18 | H6: 41243.438 | I6: 9701.736 | J6: 13265.822 | K6: 53638.267 | L6: 2826.392 | M6: 2881.676
A7: 40858 | B7: 40872 | C7: 40885 | D7: =+SUM(E7:Q7) -> 515171.32 | E7: 66555.358 | F7: 60543.806 | G7: 262115.65 | H7: 40816.622 | I7: 9422.439 | J7: 13268.025 | K7: 56232.551 | L7: 3329.418 | M7: 2887.444
A8: 40872 | B8: 40886 | C8: 40899 | D8: =+SUM(E8:Q8) -> 516909.63 | E8: 68498.128 | F8: 61200.699 | G8: 262857.86 | H8: 38164.866 | I8: 9383.139 | J8: 13435.83 | K8: 57158.745 | L8: 3391.408 | M8: 2818.962
A9: 40886 | B9: 40900 | C9: 40913 | D9: =+SUM(E9:Q9) -> 513995.42 | E9: 65143.775 | F9: 63164.127 | G9: 260268.42 | H9: 39300.632 | I9: 9194.921 | J9: 13310.698 | K9: 56870.175 | L9: 3718.794 | M9: 3023.877
A10: 40900 | B10: 40914 | C10: 40927 | D10: =+SUM(E10:Q10) -> 519184.62 | E10: 70234.655 | F10: 64527.903 | G10: 259700.78 | H10: 39374.009 | I10: 9140.738 | J10: 13380.183 | K10: 56481.354 | L10: 3321.609 | M10: 3023.385
A11: 40914 | B11: 40928 | C11: 40941 | D11: =+SUM(E11:Q11) -> 513331.44 | E11: 62432.633 | F11: 61052.933 | G11: 269108.88 | H11: 37339.004 | I11: 8117.653 | J11: 13461.149 | K11: 54842.8 | L11: 3948.081 | M11: 3028.309
A12: 40928 | B12: 40942 | C12: 40955 | D12: =+SUM(E12:Q12) -> 515535.35 | E12: 65864.887 | F12: 56631.326 | G12: 272661.48 | H12: 36763.403 | I12: 7340.093 | J12: 13486.675 | K12: 55225.913 | L12: 3943.719 | M12: 3617.854
A13: 40942 | B13: 40956 | C13: 40969 | D13: =+SUM(E13:Q13) -> 511754.27 | E13: 62129.842 | F13: 55581.355 | G13: 272403.27 | H13: 36861.453 | I13: 6903.11 | J13: 13488.336 | K13: 56814.488 | L13: 3947.723 | M13: 3624.698
A14: 40956 | B14: 40970 | C14: 40983 | D14: =+SUM(E14:Q14) -> 522057.45 | E14: 70432.061 | F14: 55998.357 | G14: 269519.7 | H14: 37487.238 | I14: 7139.326 | J14: 13703.84 | K14: 60159.486 | L14: 3993.233 | M14: 3624.204
A15: 40970 | B15: 40984 | C15: 40997 | D15: =+SUM(E15:Q15) -> 512098.32 | E15: 64594.47 | F15: 56846.615 | G15: 269837.46 | H15: 36494.707 | I15: 7410.326 | J15: 13695.18 | K15: 55422.234 | L15: 3976.28 | M15: 3821.048
... A91: 42034 | B91: 42048 | C91: 42061 | D91: =+SUM(E91:Q91) -> 756380.94 | E91: 116305.57 | F91: 103293.35 | G91: 385727.66 | H91: 28365.091 | I91: 19250.481 | J91: 10301.132 | K91: 69724.432 | L91: 13214.039 | M91: 10199.189
A93: Yükümlülük Tarihi | B93: Tesis Başlangıç Tarihi | C93: Tesis Bitiş Tarihi | D93: Toplam | E93: vadesiz mevduat ve özel cari hesap | F93: 1 aya kadar (1 ay dahil) vadeli mevduat /katılma hesabı | G93: 3 aya kadar (3 ay dahil) vadeli mevduat /katılma hesabı | H93: 6 aya kadar (6 ay dahil) vadeli mevduat /katılma hesabı | I93: 1 yıla kadar vadeli mevduat /katılma hesabı | J93: 1 yıl ve daha uzun vadeli mevduat /katılma hesabı | K93: 1 yıla kadar (1 yıl dahil) vadeli mevduat dışı yük. | L93: 2 yıla kadar (2 yıl dahil) vadeli mevduat dışı yük. | M93: 3 yıla kadar (3 yıl dahil) vadeli mevduat dışı yük. | N93: 5 yıla kadar (5 yıl dahil) vadeli mevduat dışı yük. | O93: 5 yıldan uzun vadeli mevduat dışı yük.
A94: 42048 | B94: 42062 | C94: 42075 | D94: =+SUM(E94:Q94) -> 766683.06 | E94: 119794.46 | F94: 110949.64 | G94: 388186.78 | H94: 29012.698 | I94: 18020.251 | J94: 10132.54 | K94: 67711.567 | L94: 10115.894 | M94: 2770.813 | N94: 5098.291 | O94: 4890.128
A95: 42062 | B95: 42076 | C95: 42089 | D95: =+SUM(E95:Q95) -> 763056.17 | E95: 128700.64 | F95: 102557.26 | G95: 384481.99 | H95: 26742.045 | I95: 22482.877 | J95: 10041.253 | K95: 65163.083 | L95: 10114.947 | M95: 2770.813 | N95: 5121.338 | O95: 4879.92
A96: 42076 | B96: 42090 | C96: 42103 | D96: =+SUM(E96:Q96) -> 766332.79 | E96: 123712.6 | F96: 109174.65 | G96: 385904.36 | H96: 24947.658 | I96: 22442.119 | J96: 10201.15 | K96: 67445.349 | L96: 9721.799 | M96: 2820.813 | N96: 5125.534 | O96: 4836.754
A97: 42090 | B97: 42104 | C97: 42117 | D97: =+SUM(E97:Q97) -> 764003.24 | E97: 123418.4 | F97: 106071.85 | G97: 388630.12 | H97: 22482.449 | I97: 22140.014 | J97: 10202.725 | K97: 68609.964 | L97: 9746.608 | M97: 2753.769 | N97: 5145.788 | O97: 4801.556
A98: 42104 | B98: 42118 | C98: 42131 | D98: =+SUM(E98:Q98) -> 766695.51 | E98: 119813 | F98: 103397.46 | G98: 397409.75 | H98: 20509.313 | I98: 22508.773 | J98: 10243.98 | K98: 70904.494 | L98: 9557.304 | M98: 2847.996 | N98: 4856.285 | O98: 4647.153
A99: 42118 | B99: 42132 | C99: 42145 | D99: =+SUM(E99:Q99) -> 768955.24 | E99: 125026.11 | F99: 103361.16 | G99: 398781.95 | H99: 19483.668 | I99: 22210.438 | J99: 10197.677 | K99: 67968.176 | L99: 9632.347 | M99: 2847.413 | N99: 4888.691 | O99: 4557.601
A100: 42132 | B100: 42146 | C100: 42159 | D100: =+SUM(E100:Q100) -> 762181.5 | E100: 119606.64 | F100: 108129.19 | G100: 394195.69 | H100: 19700.214 | I100: 20594.742 | J100: 10080.764 | K100: 68343.347 | L100: 9656.107 | M100: 2987.37 | N100: 4333.775 | O100: 4553.659
A101: 42146 | B101: 42160 | C101: 42173 | D101: =+SUM(E101:Q101) -> 751406.7 | E101: 120610.34 | F101: 101015.36 | G101: 388678.7 | H101: 19550.303 | I101: 21297.472 | J101: 9183.223 | K101: 69822.503 | L101: 9748.735 | M101: 2610.755 | N101: 4350.18 | O101: 4539.137
A102: 42160 | B102: 42174 | C102: 42187 | D102: =+SUM(E102:Q102) -> 753225.42 | E102: 119841.37 | F102: 103493.18 | G102: 388631.16 | H102: 20770.387 | I102: 20339.872 | J102: 9085.565 | K102: 69529.34 | L102: 10041.031 | M102: 2610.756 | N102: 4342.74 | O102: 4540.027
A103: 42174 | B103: 42188 | C103: 42201 | D103: =+SUM(E103:Q103) -> 757980.62 | E103: 123441.25 | F103: 103991.27 | G103: 389604.25 | H103: 21551.907 | I103: 19251.198 | J103: 8911.711 | K103: 69932.501 | L103: 9782.028 | M103: 2635.756 | N103: 4341.057 | O103: 4537.677
A104: 42188 | B104: 42205 | C104: 42215 | D104: =+SUM(E104:Q104) -> 748038.76 | E104: 118776.5 | F104: 100937.33 | G104: 387696.36 | H104: 25587.089 | I104: 18742.061 | J104: 8883.827 | K104: 65858.747 | L104: 9868.42 | M104: 2710.715 | N104: 4433.072 | O104: 4544.637
A105: 42205 | B105: 42216 | C105: 42229 | D105: =+SUM(E105:Q105) -> 756594.1 | E105: 129776.81 | F105: 98629.415 | G105: 386696.18 | H105: 26100.017 | I105: 18537.705 | J105: 8892.884 | K105: 66284.067 | L105: 9939.53 | M105: 2740.715 | N105: 4433.072 | O105: 4563.706
... A119: 42398 | B119: 42412 | C119: 42425 | D119: =+SUM(E119:Q119) -> 812379.89 | E119: 134249.27 | F119: 100077.6 | G119: 437189.76 | H119: 28358.017 | I119: 14893.154 | J119: 8815.867 | K119: 66725.615 | L119: 10615.559 | M119: 2724.862 | N119: 5001.261 | O119: 3728.933
A121: Yükümlülük Tarihi | B121: Tesis Başlangıç Tarihi | C121: Tesis Bitiş Tarihi | D121: Toplam | E121: vadesiz mevduat ve özel cari hesap | F121: 1 aya kadar (1 ay dahil) vadeli mevduat /katılma hesabı | G121: 3 aya kadar (3 ay dahil) vadeli mevduat /katılma hesabı | H121: 6 aya kadar (6 ay dahil) vadeli mevduat /katılma hesabı | I121: 1 yıla kadar vadeli mevduat /katılma hesabı | J121: 1 yıl ve daha uzun vadeli mevduat /katılma hesabı | K121: 1 yıla kadar (1 yıl dahil) vadeli mevduat dışı yük. | L121: 2 yıla kadar (2 yıl dahil) vadeli mevduat dışı yük. | M121: 3 yıla kadar (3 yıl dahil) vadeli mevduat dışı yük. | N121: 5 yıla kadar (5 yıl dahil) vadeli mevduat dışı yük. | O121: 5 yıldan uzun vadeli mevduat dışı yük. | P121: Müstakrizlerin Fonları
A122: 42412 | B122: 42426 | C122: 42439 | D122: =+SUM(E122:Q122) -> 825251.69 | E122: 136013.34 | F122: 104692.3 | G122: 432661.25 | H122: 30396.798 | I122: 15601.905 | J122: 8696.925 | K122: 74849.697 | L122: 10818.504 | M122: 2724.862 | N122: 5030.671 | O122: 3738.467 | P122: 26.964
A123: 42426 | B123: 42440 | C123: 42453 | D123: =+SUM(E123:Q123) -> 828618.29 | E123: 140272.63 | F123: 100423.06 | G123: 431519.08 | H123: 32893.029 | I123: 16374.642 | J123: 8573.233 | K123: 76546.953 | L123: 10588.205 | M123: 2727.52 | N123: 4947.087 | O123: 3719.747 | P123: 33.105
A124: 42440 | B124: 42454 | C124: 42467 | D124: =+SUM(E124:Q124) -> 831319.86 | E124: 133806.32 | F124: 105244.71 | G124: 435020.51 | H124: 33854.364 | I124: 16932.288 | J124: 8306.665 | K124: 76408.765 | L124: 10936.525 | M124: 2810.318 | N124: 4224.736 | O124: 3745.945 | P124: 28.707
A125: 42454 | B125: 42468 | C125: 42481 | D125: =+SUM(E125:Q125) -> 825152.2 | E125: 129776.25 | F125: 101138.66 | G125: 434031.53 | H125: 35414.742 | I125: 17564.327 | J125: 8477.635 | K125: 76700.114 | L125: 11278.85 | M125: 2810.156 | N125: 4216.567 | O125: 3715.055 | P125: 28.309
A126: 42468 | B126: 42482 | C126: 42495 | D126: =+SUM(E126:Q126) -> 825400.71 | E126: 126939.36 | F126: 104879.68 | G126: 431902.23 | H126: 37010.836 | I126: 18348.677 | J126: 8412.98 | K126: 76056.085 | L126: 11634.076 | M126: 2353.114 | N126: 4192.046 | O126: 3654.808 | P126: 16.821
A127: 42482 | B127: 42496 | C127: 42509 | D127: =+SUM(E127:Q127) -> 828006.58 | E127: 131666.7 | F127: 101094.26 | G127: 430198.21 | H127: 38521.416 | I127: 18885.393 | J127: 8605.253 | K127: 77022.498 | L127: 11978.958 | M127: 2176.114 | N127: 4190.383 | O127: 3651.086 | P127: 16.313
A128: 42496 | B128: 42510 | C128: 42523 | D128: =+SUM(E128:Q128) -> 837662.49 | E128: 132897.78 | F128: 108579.05 | G128: 433708.02 | H128: 36878.525 | I128: 18350.484 | J128: 8516.156 | K128: 76736.718 | L128: 12064.57 | M128: 2156.115 | N128: 4179.741 | O128: 3576.906 | P128: 18.426
A129: 42510 | B129: 42524 | C129: 42537 | D129: =+SUM(E129:Q129) -> 850581.56 | E129: 140023.67 | F129: 110767.46 | G129: 436612.47 | H129: 36454.852 | I129: 18567.31 | J129: 8484.711 | K129: 77547.033 | L129: 12113.074 | M129: 2230.784 | N129: 4181.433 | O129: 3581.42 | P129: 17.342
A130: 42524 | B130: 42538 | C130: 42551 | D130: =+SUM(E130:Q130) -> 853451.99 | E130: 138933.82 | F130: 114977.58 | G130: 439065.39 | H130: 34309.762 | I130: 18443.16 | J130: 8601.509 | K130: 76885.659 | L130: 12320.428 | M130: 1986.47 | N130: 4260.993 | O130: 3638.51 | P130: 28.71
...

Sheet YPZK Kal
A1: Zorunlu Karşılığa Tabi Yabancı Para Kalemler (milyon TL)
A2: Yükümlülük Tarihi | B2: Tesis Başlangıç Tarihi | C2: Tesis Bitiş Tarihi | D2: Toplam | E2: Vadesiz mevduat ve özel cari hesap | F2: 1 aya kadar (1 ay dahil) vadeli mevduat /katılma hesabı | G2: 3 aya kadar (3 ay dahil) vadeli mevduat /katılma hesabı | H2: 6 aya kadar (6 ay dahil) vadeli mevduat /katılma hesabı | I2: 1 yıla kadar vadeli mevduat /katılma hesabı | J2: 1 yıl ve daha uzun vadeli mevduat /katılma hesabı | K2: 1 yıla kadar (1 yıl dahil) vadeli mevduat dışı yük. | L2: 3 yıla kadar (3 yıl dahil) vadeli mevduat dışı yük. | M2: 3 yıldan uzun vadeli mevduat dışı yük.
A3: 40802 | B3: 40816 | C3: 40829 | D3: =SUM(E3:P3) -> 324199.99 | E3: 36409.796 | F3: 41294.269 | G3: 95783.475 | H3: 14356.369 | I3: 5489.193 | J3: 18738.226 | K3: 64039.155 | L3: 12049.312 | M3: 36040.195
A4: 40816 | B4: 40830 | C4: 40843 | D4: =SUM(E4:P4) -> 332706.16 | E4: 37269.057 | F4: 39105.043 | G4: 99615.218 | H4: 14151.408 | I4: 5693.34 | J4: 19615.767 | K4: 67465.424 | L4: 12282.651 | M4: 37508.255
A5: 40830 | B5: 40844 | C5: 40857 | D5: =SUM(E5:P5) -> 348276.28 | E5: 49902.045 | F5: 40396.509 | G5: 102615.58 | H5: 14203.79 | I5: 5509.397 | J5: 19725.2 | K5: 63982.646 | L5: 14123.682 | M5: 37817.431
A6: 40844 | B6: 40858 | C6: 40871 | D6: =SUM(E6:P6) -> 341643.06 | E6: 50073.361 | F6: 41376.14 | G6: 100227.06 | H6: 13725.366 | I6: 5351.383 | J6: 17630.743 | K6: 63993.688 | L6: 13211.841 | M6: 36053.485
A7: 40858 | B7: 40872 | C7: 40885 | D7: =SUM(E7:P7) -> 351150.42 | E7: 49649.367 | F7: 42093.036 | G7: 103261.15 | H7: 13580.723 | I7: 5255.49 | J7: 17564.176 | K7: 68834.466 | L7: 13427.111 | M7: 37484.909
A8: 40872 | B8: 40886 | C8: 40899 | D8: =SUM(E8:P8) -> 359948.2 | E8: 48529.292 | F8: 39887.499 | G8: 108750.51 | H8: 14288.066 | I8: 5472.627 | J8: 18177.044 | K8: 72553.48 | L8: 13613.327 | M8: 38676.365
A9: 40886 | B9: 40900 | C9: 40913 | D9: =SUM(E9:P9) -> 351713.46 | E9: 48681.692 | F9: 43924.642 | G9: 103856.2 | H9: 14026.117 | I9: 5302.258 | J9: 17891.914 | K9: 65600.836 | L9: 14083.224 | M9: 38346.573
A10: 40900 | B10: 40914 | C10: 40927 | D10: =SUM(E10:P10) -> 362373.91 | E10: 50167.573 | F10: 48282.803 | G10: 104161.48 | H10: 14511.141 | I10: 5350.764 | J10: 18265.036 | K10: 67528.693 | L10: 14685.903 | M10: 39420.51
A11: 40914 | B11: 40928 | C11: 40941 | D11: =SUM(E11:P11) -> 358736.53 | E11: 50726.188 | F11: 45254.478 | G11: 105807.19 | H11: 14678.684 | I11: 5201.342 | J11: 18322.818 | K11: 64699.407 | L11: 14431.579 | M11: 39614.85
A12: 40928 | B12: 40942 | C12: 40955 | D12: =SUM(E12:P12) -> 352521.3 | E12: 50616.727 | F12: 41782.069 | G12: 106916.98 | H12: 14192.43 | I12: 5237.719 | J12: 17791.444 | K12: 63252.742 | L12: 14339.555 | M12: 38391.628
A13: 40942 | B13: 40956 | C13: 40969 | D13: =SUM(E13:P13) -> 347211.3 | E13: 49964.781 | F13: 40890.311 | G13: 103827.21 | H13: 15992.894 | I13: 5560.048 | J13: 17206.112 | K13: 63212.609 | L13: 13451.162 | M13: 37106.177
A14: 40956 | B14: 40970 | C14: 40983 | D14: =SUM(E14:P14) -> 351423.7 | E14: 50145.616 | F14: 40414.266 | G14: 107763.95 | H14: 15833.914 | I14: 5607.596 | J14: 17513.001 | K14: 63397.753 | L14: 14128.596 | M14: 36619.006
... A91: 42034 | B91: 42048 | C91: 42061 | D91: =SUM(E91:P91) -> 677222.39 | E91: 81068.892 | F91: 57271.869 | G91: 195652.73 | H91: 19511.115 | I91: 10695.61 | J91: 28186.948 | K91: 148472.13 | L91: 24998.157 | M91: 111364.94
A93: Yükümlülük Tarihi | B93: Tesis Başlangıç Tarihi | C93: Tesis Bitiş Tarihi | D93: Toplam | E93: Vadesiz mevduat ve özel cari hesap | F93: 1 aya kadar (1 ay dahil) vadeli mevduat /katılma hesabı | G93: 3 aya kadar (3 ay dahil) vadeli mevduat /katılma hesabı | H93: 6 aya kadar (6 ay dahil) vadeli mevduat /katılma hesabı | I93: 1 yıla kadar vadeli mevduat /katılma hesabı | J93: 1 yıl ve daha uzun vadeli mevduat /katılma hesabı | K93: 1 yıla kadar (1 yıl dahil) vadeli mevduat dışı yük. | L93: 2 yıla kadar (2 yıl dahil) vadeli mevduat dışı yük. | M93: 3 yıla kadar (3 yıl dahil) vadeli mevduat dışı yük. | N93: 5 yıla kadar (5 yıl dahil) vadeli mevduat dışı yük. | O93: 5 yıldan uzun vadeli mevduat dışı yük.
A94: 42048 | B94: 42062 | C94: 42075 | D94: =SUM(E94:P94) -> 706031.94 | E94: 79663.313 | F94: 59195.442 | G94: 212048.24 | H94: 20351.626 | I94: 11089.308 | J94: 29124.055 | K94: 149679.05 | L94: 18366.336 | M94: 8009.61 | N94: 20035.179 | O94: 98469.779
A95: 42062 | B95: 42076 | C95: 42089 | D95: =SUM(E95:P95) -> 711008.67 | E95: 78662.024 | F95: 60834.429 | G95: 215382.47 | H95: 20507.031 | I95: 11871.662 | J95: 29180.351 | K95: 148847.65 | L95: 19262.508 | M95: 8348.682 | N95: 19688.848 | O95: 98423.02
A96: 42076 | B96: 42090 | C96: 42103 | D96: =SUM(E96:P96) -> 733418.08 | E96: 81024.408 | F96: 62926.303 | G96: 220651.42 | H96: 23781.344 | I96: 12376.562 | J96: 29031.639 | K96: 150441.26 | L96: 20709.665 | M96: 9010.585 | N96: 19975.482 | O96: 103489.41
A97: 42090 | B97: 42104 | C97: 42117 | D97: =SUM(E97:P97) -> 751737.48 | E97: 86886.245 | F97: 68909.585 | G97: 222265.1 | H97: 24952.492 | I97: 12882.933 | J97: 29956.138 | K97: 147791.92 | L97: 24375.277 | M97: 9270.81 | N97: 20174.291 | O97: 104272.7
A98: 42104 | B98: 42118 | C98: 42131 | D98: =SUM(E98:P98) -> 750225.1 | E98: 83669.491 | F98: 69426.303 | G98: 223766.46 | H98: 24402.767 | I98: 12525.196 | J98: 29335.775 | K98: 142274.79 | L98: 29050.121 | M98: 10177.416 | N98: 21383.91 | O98: 104212.88
A99: 42118 | B99: 42132 | C99: 42145 | D99: =SUM(E99:P99) -> 778178.97 | E99: 86807.878 | F99: 68042.464 | G99: 233129.33 | H99: 25771.773 | I99: 13048.216 | J99: 30305.881 | K99: 143658.52 | L99: 33330.298 | M99: 12559.561 | N99: 24280.627 | O99: 107244.42
A100: 42132 | B100: 42146 | C100: 42159 | D100: =SUM(E100:P100) -> 802679.72 | E100: 90946.424 | F100: 75865.124 | G100: 239047.39 | H100: 27334.215 | I100: 13806.081 | J100: 31094.213 | K100: 139654.79 | L100: 38655.028 | M100: 12722.767 | N100: 24697.883 | O100: 108855.81
A101: 42146 | B101: 42160 | C101: 42173 | D101: =SUM(E101:P101) -> 775226.87 | E101: 90912.364 | F101: 73046.431 | G101: 232079.62 | H101: 25840.624 | I101: 13253.922 | J101: 28488.669 | K101: 128237.79 | L101: 45047.351 | M101: 12170.977 | N101: 21281.214 | O101: 104867.9
A102: 42160 | B102: 42174 | C102: 42187 | D102: =SUM(E102:P102) -> 818698.17 | E102: 98636.749 | F102: 77891.039 | G102: 249877.27 | H102: 28808.222 | I102: 15125.473 | J102: 31480.88 | K102: 125829.55 | L102: 46872.796 | M102: 13271.158 | N102: 22452.969 | O102: 108452.06
A103: 42174 | B103: 42188 | C103: 42201 | D103: =SUM(E103:P103) -> 845013.77 | E103: 102514.55 | F103: 85616.435 | G103: 254316.51 | H103: 32149.464 | I103: 16405.138 | J103: 31701.05 | K103: 129357.43 | L103: 48440.76 | M103: 13359.128 | N103: 21628.192 | O103: 109525.1
A104: 42188 | B104: 42205 | C104: 42215 | D104: =SUM(E104:P104) -> 836376.51 | E104: 100617.63 | F104: 83487.607 | G104: 252879.09 | H104: 34683.127 | I104: 18843.644 | J104: 31274.608 | K104: 122729.96 | L104: 49130.008 | M104: 13874.594 | N104: 21201.192 | O104: 107655.04
A105: 42205 | B105: 42216 | C105: 42229 | D105: =SUM(E105:P105) -> 828375.23 | E105: 101051.85 | F105: 82022.139 | G105: 248312.51 | H105: 36662.795 | I105: 18887.403 | J105: 31212.957 | K105: 118128.6 | L105: 50620.875 | M105: 13551.797 | N105: 21311.826 | O105: 106612.48
... A119: 42398 | B119: 42412 | C119: 42425 | D119: =SUM(E119:P119) -> 908334.18 | E119: 108111.23 | F119: 80107.897 | G119: 276652.22 | H119: 32849.751 | I119: 23534.417 | J119: 45991.422 | K119: 83366.346 | L119: 89554.805 | M119: 18135.939 | N119: 29399.169 | O119: 120630.97
A121: Yükümlülük Tarihi | B121: Tesis Başlangıç Tarihi | C121: Tesis Bitiş Tarihi | D121: Toplam | E121: Vadesiz mevduat ve özel cari hesap | F121: 1 aya kadar (1 ay dahil) vadeli mevduat /katılma hesabı | G121: 3 aya kadar (3 ay dahil) vadeli mevduat /katılma hesabı | H121: 6 aya kadar (6 ay dahil) vadeli mevduat /katılma hesabı | I121: 1 yıla kadar vadeli mevduat /katılma hesabı | J121: 1 yıl ve daha uzun vadeli mevduat /katılma hesabı | K121: 1 yıla kadar (1 yıl dahil) vadeli mevduat dışı yük. | L121: 2 yıla kadar (2 yıl dahil) vadeli mevduat dışı yük. | M121: 3 yıla kadar (3 yıl dahil) vadeli mevduat dışı yük. | N121: 5 yıla kadar (5 yıl dahil) vadeli mevduat dışı yük. | O121: 5 yıldan uzun vadeli mevduat dışı yük. | P121: Müstakrizlerin Fonları
A122: 42412 | B122: 42426 | C122: 42439 | D122: =SUM(E122:P122) -> 912426.7 | E122: 101874.05 | F122: 76038.163 | G122: 267827.07 | H122: 27465.66 | I122: 19693.566 | J122: 42033.684 | K122: 117170.3 | L122: 94825.717 | M122: 18542.639 | N122: 29333.932 | O122: 117440.4 | P122: 181.531
A123: 42426 | B123: 42440 | C123: 42453 | D123: =SUM(E123:P123) -> 912015.51 | E123: 104512.29 | F123: 73589.579 | G123: 268263.58 | H123: 26972.276 | I123: 18976.476 | J123: 42558.843 | K123: 117788.15 | L123: 94127.368 | M123: 18861.461 | N123: 28964.804 | O123: 117242.4 | P123: 158.272
A124: 42440 | B124: 42454 | C124: 42467 | D124: =SUM(E124:P124) -> 901848.06 | E124: 108187.17 | F124: 73275.735 | G124: 264658.79 | H124: 26293.319 | I124: 18232.29 | J124: 41612.422 | K124: 113584.18 | L124: 92569.476 | M124: 18541.052 | N124: 28521.966 | O124: 116199.03 | P124: 172.627
A125: 42454 | B125: 42468 | C125: 42481 | D125: =SUM(E125:P125) -> 912810.66 | E125: 109417.6 | F125: 73529.206 | G125: 272670.78 | H125: 27711.85 | I125: 18818.186 | J125: 42593.966 | K125: 110915.98 | L125: 93230.104 | M125: 19345.6 | N125: 28500.785 | O125: 115912.55 | P125: 164.058
A126: 42468 | B126: 42482 | C126: 42495 | D126: =SUM(E126:P126) -> 912602.42 | E126: 106776.51 | F126: 72802.196 | G126: 271964.09 | H126: 28791.693 | I126: 19346.008 | J126: 42993.924 | K126: 108701.5 | L126: 92625.862 | M126: 18704.784 | N126: 28255.075 | O126: 121450.33 | P126: 190.453
A127: 42482 | B127: 42496 | C127: 42509 | D127: =SUM(E127:P127) -> 907583.73 | E127: 108006.95 | F127: 77593.405 | G127: 268150.48 | H127: 29561.959 | I127: 19686.652 | J127: 43349.298 | K127: 108675.04 | L127: 87166.35 | M127: 18446.266 | N127: 27932.684 | O127: 118837.49 | P127: 177.158
A128: 42496 | B128: 42510 | C128: 42523 | D128: =SUM(E128:P128) -> 939054.77 | E128: 106606.4 | F128: 73796.017 | G128: 279572.59 | H128: 31017.621 | I128: 21006.197 | J128: 45218.443 | K128: 113144.6 | L128: 93730.673 | M128: 19482.975 | N128: 28982.875 | O128: 126296.26 | P128: 200.119
A129: 42510 | B129: 42524 | C129: 42537 | D129: =SUM(E129:P129) -> 948560.86 | E129: 104111.9 | F129: 75139.538 | G129: 278873.66 | H129: 33172.64 | I129: 20678.291 | J129: 45825.269 | K129: 117543.49 | L129: 95395.012 | M129: 19001.879 | N129: 29599.717 | O129: 129031.36 | P129: 188.104
A130: 42524 | B130: 42538 | C130: 42551 | D130: =SUM(E130:P130) -> 936742.29 | E130: 103083.77 | F130: 76348.561 | G130: 272272.65 | H130: 33490.351 | I130: 22910.008 | J130: 44648.326 | K130: 116393.63 | L130: 92327.439 | M130: 18875.428 | N130: 29179.046 | O130: 127033.1 | P130: 179.976
A131: 42538 | B131: 42552 | C131: 42565 | D131: =SUM(E131:P131) -> 935852.4 | E131: 104137.16 | F131: 77413.197 | G131: 270658.66 | H131: 33729.399 | I131: 23717.115 | J131: 45289.299 | K131: 115315.1 | L131: 91620.561 | M131: 18939.058 | N131: 28964.753 | O131: 125890.73 | P131: 177.359
...

Sheet TLZK Tesis
A1: Türk Lirası Kalemler İçin Tesis Edilen Zorunlu Karşılıklar (milyon)
A2: Yükümlülük Tarihi | B2: Tesis Başlangıç Tarihi | C2: Tesis Bitiş Tarihi | D2: Tesis Edilmesi Gereken Toplam (TL) | E2: Türk Lirası Tesis Edilen | F2: Döviz Tesis Edilen (ABD doları karşılığı) | G2: Standart Altın Tesis Edilen (ABD doları karşılığı) | H2: Hurda Altın Tesis Edilen (ABD doları karşılığı)
A3: 40802 | B3: 40816 | C3: 40829 | D3: 68183.596 | E3: 62297.176 | F3: 3030.6682
A4: 40816 | B4: 40830 | C4: 40843 | D4: 65633.998 | E4: 57034.873 | F4: 4914.144
A5: 40830 | B5: 40844 | C5: 40857 | D5: 65570.188 | E5: 53128.519 | F5: 6487.1534
A6: 40844 | B6: 40858 | C6: 40871 | D6: 53493.341 | E6: 33675.334 | F6: 10258.877 | G6: 1341.7002
A7: 40858 | B7: 40872 | C7: 40885 | D7: 53902.942 | E7: 31485.571 | F7: 10526.874 | G7: 1797.9063
A8: 40872 | B8: 40886 | C8: 40899 | D8: 54167.856 | E8: 32587.755 | F8: 10428.776 | G8: 1912.2736
A9: 40886 | B9: 40900 | C9: 40913 | D9: 53808.128 | E9: 28562.579 | F9: 10621.052 | G9: 2527.4951
A10: 40900 | B10: 40914 | C10: 40927 | D10: 54387.218 | E10: 31305.465 | F10: 10384.675 | G10: 2438.0563
A11: 40914 | B11: 40928 | C11: 40941 | D11: 53831.677 | E11: 29433.92 | F11: 10319.658 | G11: 2421.0344
A12: 40928 | B12: 40942 | C12: 40955 | D12: 54093.487 | E12: 31122.518 | F12: 10580.036 | G12: 2478.315
A13: 40942 | B13: 40956 | C13: 40969 | D13: 53695.841 | E13: 28899.656 | F13: 11017.672 | G13: 2615.9609
A14: 40956 | B14: 40970 | C14: 40983 | D14: 54784.342 | E14: 30773.01 | F14: 11057.267 | G14: 2632.345
A15: 40970 | B15: 40984 | C15: 40997 | D15: 53694.279 | E15: 29162.534 | F15: 11129.877 | G15: 2691.4273
A16: 40984 | B16: 40998 | C16: 41011 | D16: 54759.297 | E16: 30854.977 | F16: 10911.254 | G16: 2702.3076
A17: 40998 | B17: 41012 | C17: 41025 | D17: 55111.467 | E17: 25822.725 | F17: 11170.174 | G17: 5601.8135
... A136: 42664 | B136: 42678 | C136: 42691 | D136: 93767.562 | E136: 33700.23 | F136: 17274.363 | G136: 11487.998
A137: 42678 | B137: 42692 | C137: 42705 | D137: 93848.46 | E137: 35254.242 | F137: 15697.965 | G137: 11379.611 | H137: 2.7705718
A138: 42692 | B138: 42706 | C138: 42719 | D138: 94965.725 | E138: 33662.401 | F138: 15786.19 | G138: 10575.694 | H138: 16.93609
A139: 42706 | B139: 42720 | C139: 42733 | D139: 93181.452 | E139: 32619.891 | F139: 15723.946 | G139: 9571.4208 | H139: 25.330186
A140: 42720 | B140: 42734 | C140: 42747 | D140: 94544.846 | E140: 35382.534 | F140: 15343.888 | G140: 8988.2238 | H140: 31.828233
A141: 42734 | B141: 42748 | C141: 42761 | D141: 94976.618 | E141: 28242.788 | F141: 16534.649 | G141: 10388.482 | H141: 41.40399
A142: 42748 | B142: 42762 | C142: 42775 | D142: 96014.989 | E142: 28424.187 | F142: 16251.184 | G142: 10689.12 | H142: 49.837143
A143: 42762 | B143: 42776 | C143: 42789 | D143: 95812.981 | E143: 24531.39 | F143: 17046.828 | G143: 11110.771 | H143: 58.827925
A144: 42776 | B144: 42790 | C144: 42803 | D144: 92621.197 | E144: 25119.92 | F144: 17371.105 | G144: 11059.801 | H144: 65.778909
A145: 42790 | B145: 42804 | C145: 42817 | D145: 92485.671 | E145: 20888.161 | F145: 19040.809 | G145: 11454.799 | H145: 72.674987
A146: 42804 | B146: 42818 | C146: 42831 | D146: 93149.672 | E146: 22414.976 | F146: 18674.413 | G146: 11327.636 | H146: 73.651332
A147: 42818 | B147: 42832 | C147: 42845 | D147: 94026.718 | E147: 21866.979 | F147: 18885.575 | G147: 12064.705 | H147: 81.64276
A148: 42832 | B148: 42846 | C148: 42859 | D148: 95275.988 | E148: 21808.35 | F148: 18388.114 | G148: 12338.466 | H148: 86.883466
... A357: 45758 | B357: 45772 | C357: 45785 | D357: 2137705.6 | E357: 2151359.6 | F357: 0 | G357: 0 | H357: 0

Sheet YPZK Tesis
A1: Yabancı Para Kalemler İçin Tesis Edilen Zorunlu Karşılıklar (milyon)
A2: Yükümlülük Tarihi | B2: Tesis Başlangıç Tarihi | C2: Tesis Bitiş Tarihi | D2: Yabancı Para Cinsinden Tesis Edilmesi Gereken Toplam (TL karşılığı) | E2: Döviz Tesis Edilen (ABD doları karşılığı) | F2: Altın Tesis Edilen (ABD doları karşılığı) | G2: Türk Lirası Cinsinden Tesis Edilmesi Gereken (TL karşılığı) | H2: Türk Lirası Cinsinden Tesis Edilen (TL karşılığı)
A3: 40802 | B3: 40816 | C3: 40829 | D3: 35584.279 | E3: 20103.951
A4: 40816 | B4: 40830 | C4: 40843 | D4: 34082.564 | E4: 18615.49
A5: 40830 | B5: 40844 | C5: 40857 | D5: 35740.836 | E5: 19087.872 | F5: 1173.128
A6: 40844 | B6: 40858 | C6: 40871 | D6: 35159.577 | E6: 18776.983 | F6: 1561.4969
A7: 40858 | B7: 40872 | C7: 40885 | D7: 36132.476 | E7: 18700.102 | F7: 1784.5376
A8: 40872 | B8: 40886 | C8: 40899 | D8: 37023.011 | E8: 18269.976 | F8: 1740.744
A9: 40886 | B9: 40900 | C9: 40913 | D9: 36130.042 | E9: 18046.728 | F9: 1897.5702
A10: 40900 | B10: 40914 | C10: 40927 | D10: 37229.458 | E10: 17979.222 | F10: 1898.6245
A11: 40914 | B11: 40928 | C11: 40941 | D11: 36823.841 | E11: 17795.573 | F11: 1933.2339
A12: 40928 | B12: 40942 | C12: 40955 | D12: 36213.842 | E12: 18052.49 | F12: 1924.8332
A13: 40942 | B13: 40956 | C13: 40969 | D13: 35723.501 | E13: 18536.648 | F13: 2018.0634
A14: 40956 | B14: 40970 | C14: 40983 | D14: 36191.54 | E14: 18450.353 | F14: 2122.1685
A15: 40970 | B15: 40984 | C15: 40997 | D15: 36440.304 | E15: 18827.381 | F15: 2160.207
A16: 40984 | B16: 40998 | C16: 41011 | D16: 37404.488 | E16: 18679.454 | F16: 2276.4966
... A93: 42062 | B93: 42076 | C93: 42089 | D93: 90217.921 | E93: 36441.017 | F93: 528.32922
A94: =+'TLZK Kal'!A96 -> 42076 | B94: 42090 | C94: 42103 | D94: 96027.752 | E94: 38116.58 | F94: 485.30056
A95: =+'TLZK Kal'!A97 -> 42090 | B95: 42104 | C95: 42117 | D95: 98143.731 | E95: 38230.747 | F95: 476.83381
A96: =+'TLZK Kal'!A98 -> 42104 | B96: 42118 | C96: 42131 | D96: 97451.153 | E96: 37941.565 | F96: 460.23664
A97: =+'TLZK Kal'!A99 -> 42118 | B97: 42132 | C97: 42145 | D97: 100748.51 | E97: 38056.289 | F97: 443.22025
A98: =+'TLZK Kal'!A100 -> 42132 | B98: 42146 | C98: 42159 | D98: 103529.1 | E98: 38642.307 | F98: 437.96567
A99: =+'TLZK Kal'!A101 -> 42146 | B99: 42160 | C99: 42173 | D99: 99840.889 | E99: 39118.052 | F99: 427.88404
A100: =+'TLZK Kal'!A102 -> 42160 | B100: 42174 | C100: 42187 | D100: 104845.94 | E100: 38931.322 | F100: 396.41035
A101: =+'TLZK Kal'!A103 -> 42174 | B101: 42188 | C101: 42201 | D101: 108490.77 | E101: 40002.497 | F101: 417.49524
A102: =+'TLZK Kal'!A104 -> 42188 | B102: 42205 | C102: 42215 | D102: 106256.53 | E102: 39481.841 | F102: 402.96892
A103: =+'TLZK Kal'!A105 -> 42205 | B103: 42216 | C103: 42229 | D103: 105014.54 | E103: 39890.861 | F103: 415.67568
A104: =+'TLZK Kal'!A106 -> 42216 | B104: 42230 | C104: 42243 | D104: 109470.87 | E104: 39596.36 | F104: 416.60273
A105: =+'TLZK Kal'!A107 -> 42230 | B105: 42244 | C105: 42257 | D105: 109923.47 | E105: 39498.194 | F105: 423.33734
... A117: =+'TLZK Kal'!A119 -> 42398 | B117: 42412 | C117: 42425 | D117: 116542.33 | E117: 39504.425 | F117: 351.73394
A118: =+'TLZK Kal'!A122 -> 42412 | B118: 42426 | C118: 42439 | D118: 122052.31 | E118: 41945.409 | F118: 396.20742
A119: =+'TLZK Kal'!A123 -> 42426 | B119: 42440 | C119: 42453 | D119: 122339.29 | E119: 42272.138 | F119: 369.80737
A120: =+'TLZK Kal'!A124 -> 42440 | B120: 42454 | C120: 42467 | D120: 120816.78 | E120: 42955.801 | F120: 377.23103
A121: =+'TLZK Kal'!A125 -> 42454 | B121: 42468 | C121: 42481 | D121: 122673.25 | E121: 43363.542 | F121: 380.81613
A122: =+'TLZK Kal'!A126 -> 42468 | B122: 42482 | C122: 42495 | D122: 122156.63 | E122: 43612.195 | F122: 393.83715
A123: =+'TLZK Kal'!A127 -> 42482 | B123: 42496 | C123: 42509 | D123: 121698.55 | E123: 43962.067 | F123: 391.66633
A124: =+'TLZK Kal'!A128 -> 42496 | B124: 42510 | C124: 42523 | D124: 126043.55 | E124: 44079.846 | F124: 393.42196
A125: =+'TLZK Kal'!A129 -> 42510 | B125: 42524 | C125: 42537 | D125: 128498.41 | E125: 44249.762 | F125: 388.01616
A126: =+'TLZK Kal'!A130 -> 42524 | B126: 42538 | C126: 42551 | D126: 127116.43 | E126: 44266.689 | F126: 393.68686
A127: =+'TLZK Kal'!A131 -> 42538 | B127: 42552 | C127: 42565 | D127: 127043.39 | E127: 44125.2 | F127: 391.13
...

Sheet ROM Kullanımı
A1: Türk Lirası Yükümlülükler İçin Rezerv Opsiyonu Mekanizması (ROM) Kullanım Oranı (%)
A2: Yükümlülük Tarihi | B2: Tesis Başlangıç Tarihi | C2: Tesis Bitiş Tarihi | D2: Döviz İmkanı (Max) % | E2: Döviz İmkanı Kullanımı % | F2: Standart Altın İmkanı (Max) % | G2: Standart Altın İmkanı Kullanımı % | H2: Hurda Altın İmkanı (Max) % | I2: Hurda Altın İmkanı Kullanımı %
A3: 40802 | B3: 40816 | C3: 40829 | D3: 10 | E3: 7.86
A4: 40816 | B4: 40830 | C4: 40843 | D4: 20 | E4: 13.82
A5: 40830 | B5: 40844 | C5: 40857 | D5: 20 | E5: 18.03
A6: 40844 | B6: 40858 | C6: 40871 | D6: 40 | E6: 33.6 | F6: 10 | G6: 4.4
A7: 40858 | B7: 40872 | C7: 40885 | D7: 40 | E7: 34.7 | F7: 10 | G7: 5.9
A8: 40872 | B8: 40886 | C8: 40899 | D8: 40 | E8: 35.7 | F8: 10 | G8: 6.5
A9: 40886 | B9: 40900 | C9: 40913 | D9: 40 | E9: 36 | F9: 10 | G9: 8.6
A10: 40900 | B10: 40914 | C10: 40927 | D10: 40 | E10: 35.9 | F10: 10 | G10: 8.4
A11: 40914 | B11: 40928 | C11: 40941 | D11: 40 | E11: 35.9 | F11: 10 | G11: 8.4
A12: 40928 | B12: 40942 | C12: 40955 | D12: 40 | E12: 35.7 | F12: 10 | G12: 8.4
A13: 40942 | B13: 40956 | C13: 40969 | D13: 40 | E13: 36 | F13: 10 | G13: 8.5
A14: 40956 | B14: 40970 | C14: 40983 | D14: 40 | E14: 35.7 | F14: 10 | G14: 8.5
A15: 40970 | B15: 40984 | C15: 40997 | D15: 40 | E15: 36.1 | F15: 10 | G15: 8.7
A16: 40984 | B16: 40998 | C16: 41011 | D16: 40 | E16: 35.8 | F16: 10 | G16: 8.9
A17: 40998 | B17: 41012 | C17: 41025 | D17: 40 | E17: 35.9 | F17: 20 | G17: 18
... A136: 42664 | B136: 42678 | C136: 42691 | D136: 60 | E136: 43.151724 | F136: 30 | G136: 21.133712
A137: 42678 | B137: 42692 | C137: 42705 | D137: 60 | E137: 41.475904 | F137: 30 | G137: 21.049262 | H137: 5 | I137: 0.0091886484
A138: 42692 | B138: 42706 | C138: 42719 | D138: 60 | E138: 44.060756 | F138: 30 | G138: 20.753737 | H138: 5 | I138: 0.059039118
A139: 42706 | B139: 42720 | C139: 42733 | D139: 60 | E139: 44.890212 | F139: 30 | G139: 20.201142 | H139: 5 | I139: 0.093737623
A140: 42720 | B140: 42734 | C140: 42747 | D140: 60 | E140: 44.105818 | F140: 30 | G140: 19.264951 | H140: 5 | I140: 0.11848992
A141: 42734 | B141: 42748 | C141: 42761 | D141: 60 | E141: 46.597924 | F141: 30 | G141: 22.223487 | H141: 5 | I141: 0.15396485
A142: 42748 | B142: 42762 | C142: 42775 | D142: 60 | E142: 47.105366 | F142: 30 | G142: 24.020465 | H142: 5 | I142: 0.19947317
A143: 42762 | B143: 42776 | C143: 42789 | D143: 60 | E143: 48.493329 | F143: 30 | G143: 24.975469 | H143: 5 | I143: 0.2354149
A144: 42776 | B144: 42790 | C144: 42803 | D144: 60 | E144: 49.031897 | F144: 30 | G144: 24.822769 | H144: 5 | I144: 0.26310513
A145: 42790 | B145: 42804 | C145: 42817 | D145: 60 | E145: 51.08421 | F145: 30 | G145: 24.908814 | H145: 5 | I145: 0.28080069
A146: 42804 | B146: 42818 | C146: 42831 | D146: 60 | E146: 51.067555 | F146: 30 | G146: 25.607161 | H146: 5 | I146: 0.29664704
A147: 42818 | B147: 42832 | C147: 42845 | D147: 60 | E147: 50.462258 | F147: 30 | G147: 25.96786 | H147: 5 | I147: 0.31374905
A148: 42832 | B148: 42846 | C148: 42859 | D148: 60 | E148: 50.130322 | F148: 30 | G148: 26.641871 | H148: 5 | I148: 0.33814667
... A310: 45100 | B310: 45114 | C310: 45127 | D310: 0 | E310: 0 | F310: 0 | G310: 0 | H310: 0 | I310: 0

Sheet ZK Ağırlıklı Ortalama Oran
A1: Yükümlülükler İçin Ağırlıklı Ortalama Zorunlu Karşılık Oranları (%)
A2: Yükümlülük Tarihi | B2: Tesis Başlangıç Tarihi | C2: Tesis Bitiş Tarihi | D2: TL Ağırlıklı Ortalama ZK Oranı | E2: YP Ağırlıklı Ortalama ZK Oranı (YP cinsinden tesis edilmesi gereken kısım için)*
A3: 40550 | B3: 40564 | C3: 40577 | D3: 7.4246928 | E3: 11
A4: 40564 | B4: 40578 | C4: 40591 | D4: 7.4161596 | E4: 11.000002
A5: 40578 | B5: 40592 | C5: 40605 | D5: 9.4211751 | E5: 11
A6: 40592 | B6: 40606 | C6: 40619 | D6: 9.4380219 | E6: 11
A7: 40606 | B7: 40620 | C7: 40633 | D7: 9.3956152 | E7: 11
A8: 40620 | B8: 40634 | C8: 40647 | D8: 9.3881083 | E8: 10.999999
A9: 40634 | B9: 40648 | C9: 40661 | D9: 13.198812 | E9: 11
A10: 40648 | B10: 40662 | C10: 40675 | D10: 13.104716 | E10: 10.999999
A11: 40662 | B11: 40676 | C11: 40689 | D11: 13.295119 | E11: 11.827567
A12: 40676 | B12: 40690 | C12: 40703 | D12: 13.278397 | E12: 11.824581
A13: 40690 | B13: 40704 | C13: 40717 | D13: 13.239727 | E13: 11.823243
A14: 40704 | B14: 40718 | C14: 40731 | D14: 13.173042 | E14: 11.819162
... A375: 45758 | B375: 45772 | C375: 45785 | D375: 16.207422 | E375: 21.121882
A377: *Yabancı para cinsinden mevduat/katılım fonu (yurt dışı bankalar mevduatı/katılım fonu ve kıymetli maden depo hesapları hariç) için TL cinsinden tesis edilmesi gereken ilave zorunlu karşılık oranı tüm vadelerde yüzde 4’tür.
